<?xml version="1.0" ?>
<!-- =================================================================================== -->
<!-- |    This document was autogenerated by xacro from mobilebot.xacro                | -->
<!-- |    EDITING THIS FILE BY HAND IS NOT RECOMMENDED                                 | -->
<!-- =================================================================================== -->
<robot name="mobilebot">
  <material name="silver">
    <color rgba="0.700 0.700 0.700 1.000"/>
  </material>
  <transmission name="Revolute 2_tran">
    <type>transmission_interface/SimpleTransmission</type>
    <joint name="Revolute 2">
      <hardwareInterface>hardware_interface/EffortJointInterface</hardwareInterface>
    </joint>
    <actuator name="Revolute 2_actr">
      <hardwareInterface>hardware_interface/EffortJointInterface</hardwareInterface>
      <mechanicalReduction>1</mechanicalReduction>
    </actuator>
  </transmission>
  <transmission name="Revolute 3_tran">
    <type>transmission_interface/SimpleTransmission</type>
    <joint name="Revolute 3">
      <hardwareInterface>hardware_interface/EffortJointInterface</hardwareInterface>
    </joint>
    <actuator name="Revolute 3_actr">
      <hardwareInterface>hardware_interface/EffortJointInterface</hardwareInterface>
      <mechanicalReduction>1</mechanicalReduction>
    </actuator>
  </transmission>
  <transmission name="Revolute 6_tran">
    <type>transmission_interface/SimpleTransmission</type>
    <joint name="Revolute 6">
      <hardwareInterface>hardware_interface/EffortJointInterface</hardwareInterface>
    </joint>
    <actuator name="Revolute 6_actr">
      <hardwareInterface>hardware_interface/EffortJointInterface</hardwareInterface>
      <mechanicalReduction>1</mechanicalReduction>
    </actuator>
  </transmission>
  <transmission name="Revolute 7_tran">
    <type>transmission_interface/SimpleTransmission</type>
    <joint name="Revolute 7">
      <hardwareInterface>hardware_interface/EffortJointInterface</hardwareInterface>
    </joint>
    <actuator name="Revolute 7_actr">
      <hardwareInterface>hardware_interface/EffortJointInterface</hardwareInterface>
      <mechanicalReduction>1</mechanicalReduction>
    </actuator>
  </transmission>
  <!-- SENSOR SYSTEM PLUGIN - Required for LiDAR to work -->
  <gazebo>
    <plugin filename="libgz-sim8-sensors-system.so" name="gz::sim::systems::Sensors">
      <render_engine>ogre2</render_engine>
    </plugin>
  </gazebo>
  <!-- DIFF DRIVE PLUGIN -->
  <gazebo>
    <plugin filename="libgz-sim8-diff-drive-system.so" name="gz::sim::systems::DiffDrive">
      <left_joint>Revolute 2</left_joint>
      <left_joint>Revolute 3</left_joint>
      <right_joint>Revolute 7</right_joint>
      <right_joint>Revolute 6</right_joint>
      <wheel_separation>0.27</wheel_separation>
      <wheel_radius>0.04</wheel_radius>
      <topic>cmd_vel</topic>
      <odom_topic>odom</odom_topic>
      <frame_id>odom</frame_id>
      <child_frame_id>base_link</child_frame_id>
    </plugin>
  </gazebo>
  <!-- BASE LINK PHYSICS -->
  <gazebo reference="base_link">
    <mu1>0.2</mu1>
    <mu2>0.2</mu2>
    <selfCollide>true</selfCollide>
    <gravity>true</gravity>
  </gazebo>
  <!-- WHEEL PHYSICS -->
  <gazebo reference="leftw_front_1">
    <mu1>0.8</mu1>
    <mu2>0.8</mu2>
    <selfCollide>true</selfCollide>
  </gazebo>
  <gazebo reference="leftw_back_1">
    <mu1>0.8</mu1>
    <mu2>0.8</mu2>
    <selfCollide>true</selfCollide>
  </gazebo>
  <gazebo reference="rightw_back_1">
    <mu1>0.8</mu1>
    <mu2>0.8</mu2>
    <selfCollide>true</selfCollide>
  </gazebo>
  <gazebo reference="rightw_front_1">
    <mu1>0.8</mu1>
    <mu2>0.8</mu2>
    <selfCollide>true</selfCollide>
  </gazebo>
  <!-- LIDAR SENSOR -->
  <gazebo reference="lidar_link">
    <sensor name="lidar" type="lidar">
      <topic>lidar</topic>
      <update_rate>10</update_rate>
      <lidar>
        <scan>
          <horizontal>
            <samples>360</samples>
            <resolution>1</resolution>
            <min_angle>-3.14159</min_angle>
            <max_angle>3.14159</max_angle>
          </horizontal>
        </scan>
        <range>
          <min>0.1</min>
          <max>10.0</max>
          <resolution>0.01</resolution>
        </range>
        <noise>
          <type>gaussian</type>
          <mean>0</mean>
          <stddev>0.01</stddev>
        </noise>
      </lidar>
      <always_on>true</always_on>
      <visualize>true</visualize>
    </sensor>
  </gazebo>
  <!-- BASE LINK -->
  <link name="base_link">
    <inertial>
      <origin rpy="0 0 0" xyz="0.0005792285328756672 7.970344944745154e-07 0.0403411412663239"/>
      <mass value="4.079939844889388"/>
      <inertia ixx="0.023714" ixy="-0.0" ixz="-0.000114" iyy="0.044684" iyz="-0.0" izz="0.066606"/>
    </inertial>
    <visual>
      <origin rpy="0 0 0" xyz="0 0 0"/>
      <geometry>
        <mesh filename="package://mobilebot_description/meshes/base_link.stl" scale="0.001 0.001 0.001"/>
      </geometry>
      <material name="silver"/>
    </visual>
    <collision>
      <origin rpy="0 0 0" xyz="0 0 0"/>
      <geometry>
        <mesh filename="package://mobilebot_description/meshes/base_link.stl" scale="0.001 0.001 0.001"/>
      </geometry>
    </collision>
  </link>
  <!-- LEFT FRONT WHEEL -->
  <link name="leftw_front_1">
    <inertial>
      <origin rpy="0 0 0" xyz="-6.938893903907228e-17 -0.007500000000000034 1.3877787807814457e-17"/>
      <mass value="0.07012034802812415"/>
      <inertia ixx="2.9e-05" ixy="0.0" ixz="-0.0" iyy="5.6e-05" iyz="-0.0" izz="2.9e-05"/>
    </inertial>
    <visual>
      <origin rpy="0 0 0" xyz="0.115 0.135 -0.04"/>
      <geometry>
        <mesh filename="package://mobilebot_description/meshes/leftw_front_1.stl" scale="0.001 0.001 0.001"/>
      </geometry>
      <material name="silver"/>
    </visual>
    <collision>
      <origin rpy="0 0 0" xyz="0.115 0.135 -0.04"/>
      <geometry>
        <mesh filename="package://mobilebot_description/meshes/leftw_front_1.stl" scale="0.001 0.001 0.001"/>
      </geometry>
    </collision>
  </link>
  <!-- LEFT BACK WHEEL -->
  <link name="leftw_back_1">
    <inertial>
      <origin rpy="0 0 0" xyz="-5.551115123125783e-17 -0.007500000000000007 2.7755575615628914e-17"/>
      <mass value="0.07012034802812417"/>
      <inertia ixx="2.9e-05" ixy="-0.0" ixz="0.0" iyy="5.6e-05" iyz="-0.0" izz="2.9e-05"/>
    </inertial>
    <visual>
      <origin rpy="0 0 0" xyz="-0.115 0.135 -0.04"/>
      <geometry>
        <mesh filename="package://mobilebot_description/meshes/leftw_back_1.stl" scale="0.001 0.001 0.001"/>
      </geometry>
      <material name="silver"/>
    </visual>
    <collision>
      <origin rpy="0 0 0" xyz="-0.115 0.135 -0.04"/>
      <geometry>
        <mesh filename="package://mobilebot_description/meshes/leftw_back_1.stl" scale="0.001 0.001 0.001"/>
      </geometry>
    </collision>
  </link>
  <!-- RIGHT BACK WHEEL -->
  <link name="rightw_back_1">
    <inertial>
      <origin rpy="0 0 0" xyz="-1.5265566588595902e-16 0.007500000000000007 3.469446951953614e-17"/>
      <mass value="0.07012034802812417"/>
      <inertia ixx="2.9e-05" ixy="0.0" ixz="-0.0" iyy="5.6e-05" iyz="-0.0" izz="2.9e-05"/>
    </inertial>
    <visual>
      <origin rpy="0 0 0" xyz="-0.115 -0.135 -0.04"/>
      <geometry>
        <mesh filename="package://mobilebot_description/meshes/rightw_back_1.stl" scale="0.001 0.001 0.001"/>
      </geometry>
      <material name="silver"/>
    </visual>
    <collision>
      <origin rpy="0 0 0" xyz="-0.115 -0.135 -0.04"/>
      <geometry>
        <mesh filename="package://mobilebot_description/meshes/rightw_back_1.stl" scale="0.001 0.001 0.001"/>
      </geometry>
    </collision>
  </link>
  <!-- RIGHT FRONT WHEEL -->
  <link name="rightw_front_1">
    <inertial>
      <origin rpy="0 0 0" xyz="0.0 0.007500000000000007 5.551115123125783e-17"/>
      <mass value="0.07012034802812417"/>
      <inertia ixx="2.9e-05" ixy="0.0" ixz="-0.0" iyy="5.6e-05" iyz="-0.0" izz="2.9e-05"/>
    </inertial>
    <visual>
      <origin rpy="0 0 0" xyz="0.115 -0.135 -0.04"/>
      <geometry>
        <mesh filename="package://mobilebot_description/meshes/rightw_front_1.stl" scale="0.001 0.001 0.001"/>
      </geometry>
      <material name="silver"/>
    </visual>
    <collision>
      <origin rpy="0 0 0" xyz="0.115 -0.135 -0.04"/>
      <geometry>
        <mesh filename="package://mobilebot_description/meshes/rightw_front_1.stl" scale="0.001 0.001 0.001"/>
      </geometry>
    </collision>
  </link>
  <!-- LIDAR LINK -->
  <link name="lidar_link">
    <inertial>
      <mass value="0.1"/>
      <inertia ixx="0.001" ixy="0" ixz="0" iyy="0.001" iyz="0" izz="0.001"/>
    </inertial>
    <visual>
      <geometry>
        <cylinder length="0.04" radius="0.03"/>
      </geometry>
      <material name="silver"/>
    </visual>
    <collision>
      <geometry>
        <cylinder length="0.04" radius="0.03"/>
      </geometry>
    </collision>
  </link>
  <!-- WHEEL JOINTS -->
  <joint name="Revolute 2" type="continuous">
    <origin rpy="0 0 0" xyz="-0.115 -0.135 0.04"/>
    <parent link="base_link"/>
    <child link="leftw_front_1"/>
    <axis xyz="0.0 1.0 0.0"/>
  </joint>
  <joint name="Revolute 3" type="continuous">
    <origin rpy="0 0 0" xyz="0.115 -0.135 0.04"/>
    <parent link="base_link"/>
    <child link="leftw_back_1"/>
    <axis xyz="0.0 1.0 0.0"/>
  </joint>
  <joint name="Revolute 6" type="continuous">
    <origin rpy="0 0 0" xyz="0.115 0.135 0.04"/>
    <parent link="base_link"/>
    <child link="rightw_back_1"/>
    <axis xyz="0.0 1.0 0.0"/>
  </joint>
  <joint name="Revolute 7" type="continuous">
    <origin rpy="0 0 0" xyz="-0.115 0.135 0.04"/>
    <parent link="base_link"/>
    <child link="rightw_front_1"/>
    <axis xyz="0.0 1.0 0.0"/>
  </joint>
  <!-- LIDAR JOINT - mounted at front -->
  <joint name="lidar_joint" type="fixed">
    <parent link="base_link"/>
    <child link="lidar_link"/>
    <origin rpy="0 0 0" xyz="-0.1 0.0 0.08"/>
  </joint>
</robot>
